<?xml version="1.0"?>
<robot name="ev3_robot_gyro_car"
       xmlns:xi="http://www.w3.org/2001/XInclude"
       xmlns:gazebo="http://playerstage.sourceforge.net/gazebo/xmlschema/#gz"
       xmlns:model="http://playerstage.sourceforge.net/gazebo/xmlschema/#model"
       xmlns:sensor="http://playerstage.sourceforge.net/gazebo/xmlschema/#sensor"
       xmlns:body="http://playerstage.sourceforge.net/gazebo/xmlschema/#body"
       xmlns:geom="http://playerstage.sourceforge.net/gazebo/xmlschema/#geom"
       xmlns:joint="http://playerstage.sourceforge.net/gazebo/xmlschema/#joint"
       xmlns:interface="http://playerstage.sourceforge.net/gazebo/xmlschema/#interface"
       xmlns:rendering="http://playerstage.sourceforge.net/gazebo/xmlschema/#rendering"
       xmlns:renderable="http://playerstage.sourceforge.net/gazebo/xmlschema/#renderable"
       xmlns:controller="http://playerstage.sourceforge.net/gazebo/xmlschema/#controller"
       xmlns:physics="http://playerstage.sourceforge.net/gazebo/xmlschema/#physics">
  <link name="base_link"/>

  <joint name="base_joint" type="fixed">
    <parent link="base_link"/>
    <child link="body_link"/>
    <origin xyz="0 0 0.075" rpy="0 0 0" />
    <axis xyz="0 0 1" />
  </joint>

  <link name="body_link">
    <visual>
      <origin xyz="0 0 0" rpy="0 0 0" />
      <geometry>
        <box size="0.15 0.09 0.1"/>
      </geometry>
    </visual>
  </link>

  <joint name="r_wheel_joint" type="continuous">
    <parent link="body_link"/>
    <child link="r_wheel_link"/>
    <origin xyz="0.015 -0.06 -0.05" rpy="1.57079 0 0" />
    <axis xyz="0 0 -1" />
  </joint>

  <link name="r_wheel_link">
    <visual>
      <origin xyz="0 0 0" rpy="0 0 0" />
      <geometry>
        <cylinder length="0.028" radius="0.028"/>
      </geometry>
    </visual>
  </link>

  <joint name="l_wheel_joint" type="continuous">
    <parent link="body_link"/>
    <child link="l_wheel_link"/>
    <origin xyz="0.015 0.06 -0.05" rpy="-1.57079 0 0" />
    <axis xyz="0 0 1" />
  </joint>

  <link name="l_wheel_link">
    <visual>
      <origin xyz="0 0 0" rpy="0 0 0" />
      <geometry>
        <cylinder length="0.028" radius="0.028"/>
      </geometry>
    </visual>
  </link>

  <joint name="ultrasonic_joint" type="fixed">
    <parent link="body_link"/>
    <child link="ultrasonic_link"/>
    <origin xyz="0.06 0 -0.05" rpy="0 0 0" />
    <axis xyz="0 0 1" />
  </joint>

  <link name="ultrasonic_link">
    <visual>
      <origin xyz="0 0 0" rpy="0 1.57079 0" />
      <geometry>
        <box size="0.02 0.055 0.02"/>
      </geometry>
    </visual>
  </link>

  <joint name="gyro_joint" type="fixed">
    <parent link="body_link"/>
    <child link="gyro_link"/>
    <origin xyz="-0.09 0 0.065" rpy="0 1.57079 0" />
    <axis xyz="0 0 1" />
  </joint>

  <link name="gyro_link">
    <visual>
      <origin xyz="0 0 0" rpy="0 0 0" />
      <geometry>
        <box size="0.04 0.02 0.02"/>
      </geometry>
    </visual>
  </link>
</robot>
